Workbook

Sheet Legenda
A1: Planejamento de Produto e Desenvolvimento — Confecção HMZT
A3: Fonte | B3: Prints das páginas da Lunfe Malhas (29–30/09/2026) + textos "Descrição Geral" colados pelo Angelo. Fichas em docs/shop-confeccao/catalogo, dossiês em /dossies, prompts em /prompts.
A4: Abas | B4: Resumo · Regras Fornecedor · uma aba por produto (P01–P29) · Não Catalogados · Pendências Gerais · Prompts Lookbook (um prompt por foto)
A6: Convenção de cores
A7: Texto azul | B7: Valor digitado (dado do fornecedor ou estimativa). Pode ser editado.
A8: Texto preto | B8: Fórmula — não editar.
A9: Texto verde | B9: Fórmula que puxa de outra aba.
A10: Fundo amarelo | B10: Estimativa HMZT ou campo a preencher — revisar quando chegar o orçamento real.
A11: Fundo vermelho claro | B11: Contradição, risco ou dado faltando.
A13: Marcas nas tabelas
A14: ✅ | B14: Dado técnico declarado pelo fornecedor
A15: 📣 | B15: Alegação de marketing do fornecedor — NÃO usar como fato na comunicação HMZT
A16: ⚠️ | B16: Contradição ou erro encontrado
A17: 🟢 | B17: Recomendação HMZT
A19: Como usar | B19: 1) Atualize descontos/Pix em "Regras Fornecedor" — todas as abas recalculam. 2) Em cada produto, preencha os custos amarelos (personalização, frete, embalagem, impostos) quando chegarem os orçamentos. 3) Ajuste o preço de venda HMZT e veja a margem.

Sheet Resumo
A1: Resumo do catálogo — 29 produtos Lunfe
A3: Produto | B3: Categoria | C3: Código HMZT | D3: Nome | E3: Linha HMZT | F3: Modelagem | G3: Tecido | H3: Gramatura | I3: Composição | J3: Nº cores | K3: Preço base | L3: Lote 20 + Pix | M3: Topo (300+) | N3: Custo HMZT est. | O3: Preço venda HMZT | P3: Margem bruta % | Q3: Risco / atenção
A4: P01 | B4: Camiseta | C4: HMZT-P01-OVS-SUE300 | D4: Camiseta Oversized Suedine Peruano 300g | E4: Heavy (oversized) | F4: Oversized | G4: Suedine | H4: 300 g/m² | I4: 52% CO / 48% PES | J4: 3 | K4: =P01!$B$47 | L4: =P01!E49 | M4: =P01!D53 | N4: =P01!B59 | O4: =P01!B60 | P4: =P01!B63 | Q4: "Peruano" no nome não é algodão peruano
A5: P02 | B5: Camiseta | C5: HMZT-P02-OVS-ALG185 | D5: Camiseta Oversized Drop Shoulder Algodão Penteado 185g | E5: Essencial — oversized (drops com estampa, eventos) | F5: Oversized drop shoulder — ombro caído, corpo amplo, comprimento alongado | G5: Meia malha lisa, sem acabamento especial | H5: 185 g/m² (resumo do topo diz 300 g/m²) | I5: 100% algodão penteado | J5: 2 | K5: =P02!$B$64 | L5: =P02!E66 | M5: =P02!D70 | N5: =P02!B76 | O5: =P02!B77 | P5: =P02!B80 | Q5: Resumo do topo diz '100% Algodão Penteado 300g/m²'; ficha técnica e FAQ dizem 185 g/m².
A6: P03 | B6: Camiseta | C6: HMZT-P03-REG-PIM165 | D6: Camiseta Pima Cotton 165g | E6: Premium (principal) | F6: Regular | G6: Pima | H6: 165 g/m² | I6: 100% Pima | J6: 8 | K6: =P03!$B$61 | L6: =P03!E63 | M6: =P03!D67 | N6: =P03!B73 | O6: =P03!B74 | P6: =P03!B77 | Q6: Comprovar Pima
A7: P04 | B7: Camiseta | C7: HMZT-P04-REG-SUE300 | D7: Camiseta Suedine Peruano 300g Regular Fit | E7: Heavy (principal) | F7: Regular | G7: Suedine | H7: 300 g/m² | I7: 52% CO / 48% PES | J7: 5 | K7: =P04!$B$57 | L7: =P04!E59 | M7: =P04!D63 | N7: =P04!B69 | O7: =P04!B70 | P7: =P04!B73 | Q7: "Peruano" no nome; cartela divergente
A8: P05 | B8: Camiseta | C8: HMZT-P05-REG-XJG300 / -OVS- | D8: Camiseta Chinese Heavyweight 300g | E8: Heavy (alternativa ⚠️ Xinjiang) | F8: Regular + Oversized | G8: Algodão Xinjiang 2 cabos | H8: 300 g/m² | I8: 100% CO | J8: 4 | K8: =P05!$B$65 | L8: =P05!E67 | M8: =P05!D71 | N8: =P05!B77 | O8: =P05!B78 | P8: =P05!B81 | Q8: Origem Xinjiang
A9: P06 | B9: Camiseta | C9: HMZT-P06-REG-XJG160 | D9: Camiseta Chinese Cotton 160g | E9: Essencial (alternativa ⚠️ Xinjiang) | F9: Regular | G9: Algodão Xinjiang | H9: 160 g/m² ⚠️ | I9: 100% CO | J9: 5 | K9: =P06!$B$56 | L9: =P06!E58 | M9: =P06!D62 | N9: =P06!B68 | O9: =P06!B69 | P9: =P06!B72 | Q9: Origem Xinjiang; 160 × 180 g
A10: P07 | B10: Camiseta | C10: HMZT-P07-REG-PER220 | D10: Camiseta Cotton Peruano 220g com Elastano | E10: Premium (alternativa) | F10: Regular | G10: Algodão peruano + elastano | H10: 220 g/m² | I10: 96% CO / 4% EL | J10: 6 | K10: =P07!$B$59 | L10: =P07!E61 | M10: =P07!D65 | N10: =P07!B71 | O10: =P07!B72 | P10: =P07!B75 | Q10: Esgotado na página; variedade do algodão
A11: P08 | B11: Camiseta | C11: HMZT-P08-REG-EGY50 | D11: Camiseta Egyptian Cotton Fio 50/1 com Elastano | E11: Topo / Assinatura (inclui unissex) | F11: Regular | G11: Algodão egípcio 50/1 + elastano | H11: 170 g/m² | I11: 91,5% CO / 8,5% EL | J11: 7 | K11: =P08!$B$58 | L11: =P08!E60 | M11: =P08!D64 | N11: =P08!B70 | O11: =P08!B71 | P11: =P08!B74 | Q11: Comprovar egípcio; nº OEKO-TEX
A12: P09 | B12: Camiseta | C12: HMZT-P09-REG-SUELT | D12: Camiseta Suedine Light | E12: Suedine light | F12: Regular | G12: Suedine light | H12: não informada ⚠️ | I12: algodão + sintético (% ?) | J12: 5 | K12: =P09!$B$50 | L12: =P09!E52 | M12: =P09!D56 | N12: =P09!B62 | O12: =P09!B63 | P12: =P09!B66 | Q12: Faltam gramatura e composição
A13: P10 | B13: Camiseta | C13: HMZT-P10-OVS-SUEALG300 | D13: Camiseta Oversized Básica Suedine 300GSM (100% algodão) | E13: Heavy — oversized (alternativa mais barata à P01) | F13: True oversized boxy, ombros caídos | G13: Malha suedine 'interlock de dupla frontura' | H13: 300 g/m², zero transparência | I13: 100% algodão (P01, também suedine 300g, é 52/48) | J13: 6 | K13: =P10!$B$48 | L13: =P10!E50 | M13: =P10!D54 | N13: =P10!B60 | O13: =P10!B61 | P13: =P10!B64 | Q13: Composição 100% algodão, R$ 42,00 × P01 (Oversized Suedine Peruano 300g) 52% algodão/48% poliéster, R$ 54,00.
A14: P11 | B14: Camiseta | C14: HMZT-P11-REG-PA160 | D14: Camiseta Custo Inteligente Malha Algodão/Poliéster 160g | E14: Uniformes & Eventos (B2B) — fora da vitrine | F14: Regular fit | G14: — | H14: 160 g/m² | I14: Meia malha algodão + poliéster — % não informado | J14: 6 | K14: =P11!$B$60 | L14: =P11!E62 | M14: =P11!D66 | N14: =P11!B72 | O14: =P11!B73 | P14: =P11!B76 | Q14: Seletor da página: R$ 39,90. Descrição: base R$ 28,99 e 'a partir de R$ 20,29' (= 28,99 × 0,70).
A15: P12 | B15: Camiseta | C15: HMZT-P12-REG-BCI280 | D15: Camiseta Malhão Compact Algodão BCI 280g | E15: Heavy — regular 100% algodão | F15: Regular fit unissex (tabela masculina) | G15: — | H15: 280 g/m² | I15: 100% algodão BCI | J15: 8 | K15: =P12!$B$57 | L15: =P12!E59 | M15: =P12!D63 | N15: =P12!B69 | O15: =P12!B70 | P15: =P12!B73 | Q15: FAQ chama o fio 26/1 de 'fino'; 26/1 é mais grosso que 30/1.
A16: P13 | B16: Camiseta | C16: HMZT-P13-REG-EST175 | D16: Camiseta Estonada Regular 175g (Outras Cores) | E16: Lavada/Vintage (nova) — base regular | F16: Regular (tabela padrão Lunfe) | G16: — | H16: 175 g/m² (texto) × 180 GSM (banner da galeria) | I16: 100% algodão penteado | J16: 6 | K16: =P13!$B$57 | L16: =P13!E59 | M16: =P13!D63 | N16: =P13!B69 | O16: =P13!B70 | P16: =P13!B73 | Q16: P13 × P14 são quase duplicados. Mesma composição, gramatura, preço (R$ 37,26), tabela de desconto, tabela de medidas e sessão de fotos. Muda só o EAN (7897564701282 × 7892948548590), o título ("Vintage") e a cartela. O "-oc" do endereço provavelmente é "outras cores" (hipótese).
A17: P14 | B17: Camiseta | C17: HMZT-P14-REG-EST175 | D17: Camiseta Estonada Regular 175g | E17: Lavada/Vintage (nova) — base regular | F17: Regular (tabela padrão Lunfe) | G17: — | H17: 175 g/m² (texto) × 180 GSM (banner da galeria) | I17: 100% algodão penteado | J17: 6 | K17: =P14!$B$60 | L17: =P14!E62 | M17: =P14!D66 | N17: =P14!B72 | O17: =P14!B73 | P17: =P14!B76 | Q17: P14 × P13: o P13 é a mesma peça (mesma ficha, preço, medidas e fotos) com outro EAN e outra cartela — o texto do P13 até copia as cores do P14.
A18: P15 | B18: Camiseta | C18: HMZT-P15-REG-ESN175 | D18: Camiseta Estonada Neon Regular 175g | E18: Lavada/Vintage — cápsula de verão (drop) | F18: Regular (tabela padrão Lunfe) | G18: — | H18: 175 g/m² (texto) × 180 GSM (banner da galeria) | I18: 100% algodão penteado | J18: 6 | K18: =P15!$B$57 | L18: =P15!E59 | M18: =P15!D63 | N18: =P15!B69 | O18: =P15!B70 | P18: =P15!B73 | Q18: Neon + algodão: corante fluorescente em algodão tem solidez à luz baixa — desbota com sol e lavagem mais rápido que cor comum. O próprio FAQ recomenda "lavar do avesso em água fria para prolongar a intensidade", o que contradiz "vibração estável".
A19: P16 | B19: Camiseta | C19: HMZT-P16-OVS-EST175 | D19: Camiseta Estonada Oversized 175g | E19: Lavada/Vintage (nova) — base oversized | F19: Oversized (ombro caído, corpo amplo e alongado) | G19: — | H19: 175 g/m² (texto) × 180 GSM (banner da galeria) | I19: 100% algodão penteado | J19: 15 | K19: =P16!$B$65 | L19: =P16!E67 | M19: =P16!D71 | N19: =P16!B77 | O19: =P16!B78 | P19: =P16!B81 | Q19: Mangas × P17: o texto do P17 diz que a modelagem é idêntica, mas as mangas diferem (P16: 24–28 cm, +1 por tamanho; P17: 22–30 cm, +2 por tamanho).
A20: P17 | B20: Camiseta | C20: HMZT-P17-OVS-ESB175 | D20: Camiseta Estonada Oversized com Bolso 175g | E20: Lavada/Vintage — destaque oversized com bolso (após reposição) | F20: Oversized com bolso no peito | G20: — | H20: 175 g/m² (texto) × 180 GSM (banner da galeria) | I20: 100% algodão penteado | J20: 3 | K20: =P17!$B$55 | L20: =P17!E57 | M20: =P17!D61 | N20: =P17!B67 | O20: =P17!B68 | P20: =P17!B71 | Q20: Conferência com a página do P02: o comparativo do P02 diz "Estonada Oversized Bolso 175g, 100% algodão penteado 30/1, 3 cores, R$ 39,78" — bate com esta página ✅ (175 g, 30/1, Verde Musgo/Azul/Preto, base R$ 39,78, mínimo R$ 27,85). E o "Esse acabou" do P02 também bate: a própria página do P17 está esgotada (sem seletor, sem preço no topo). O P02 ainda diz "peso ao vestir: leve" e "volume de vendas alto" 📣.
A21: P18 | B21: Camiseta | C21: HMZT-P18-REG-RIB240 | D21: Camiseta Rib Wide Texture 240g — canelado largo vertical | E21: Textura (nova) — alternativa vertical; esgotada | F21: Regular fit | G21: Malha (tricô) texturizada — o texto chama de "tecelagem", termo errado para malha | H21: 240 g/m² | I21: 52% algodão + 48% poliéster | J21: 5 | K21: =P18!$B$63 | L21: =P18!E65 | M21: =P18!D69 | N21: =P18!B75 | O21: =P18!B76 | P21: =P18!B79 | Q21: Estoque: página diz "Esse acabou"; FAQ diz 5 cores em estoque com despacho em 24h.
A22: P19 | B22: Camiseta | C22: HMZT-P19-REG-PLS240 | D22: Camiseta Plissé Texture 240g — canelado vertical largo acetinado | E22: Textura (nova) — cápsula noturna / drop | F22: Regular fit | G22: Malha (tricô) texturizada — o texto chama de "tecelagem", termo errado para malha | H22: 240 g/m² | I22: 52% algodão + 48% poliéster | J22: 6 | K22: =P19!$B$64 | L22: =P19!E66 | M22: =P19!D70 | N22: =P19!B76 | O22: =P19!B77 | P22: =P19!B80 | Q22: Cores: o texto lista 5 cores sem cinza; o seletor da página mostra só Cinza e Preto; as fotos são cinza e preto.
A23: P20 | B23: Camiseta | C23: HMZT-P20-REG-RPL240 | D23: Camiseta Ripple Texture 240g — micro-ondulação horizontal | E23: Textura (nova) — base principal (quiet luxury, sob blazer) | F23: Regular fit | G23: Malha (tricô) texturizada — o texto chama de "tecelagem", termo errado para malha | H23: 240 g/m² | I23: 52% algodão + 48% poliéster | J23: 8 | K23: =P20!$B$65 | L23: =P20!E67 | M23: =P20!D71 | N23: =P20!B77 | O23: =P20!B78 | P23: =P20!B81 | Q23: Cores: texto (5) × seletor (6) × fotos (5) não batem; Azul, Verde e Cinza não existem no texto; Bege e Marinho não existem no seletor.
A24: P21 | B24: Camiseta | C24: HMZT-P21-REG-WFK240 | D24: Camiseta Waffle Knit Texture 240g — faixas trançadas horizontais | E24: Textura (nova) — casual de fim de semana e presente | F24: Regular fit | G24: Malha (tricô) texturizada — o texto chama de "tecelagem", termo errado para malha | H24: 240 g/m² | I24: 52% algodão + 48% poliéster | J24: 5 | K24: =P21!$B$62 | L24: =P21!E64 | M24: =P21!D68 | N24: =P21!B74 | O24: =P21!B75 | P24: =P21!B78 | Q24: Cores: seletor mostra Marrom, Preto, Off White; fotos mostram bege, preto, off-white; texto lista 5 cores.
A25: P22 | B25: Camiseta | C25: HMZT-P22-REG-PIQ240 | D25: Camiseta Piqué Texture 240g — micro-mesh | E25: Textura (nova) — piquê "old money" e uniforme B2B bordado | F25: Regular fit (oversized "em estudo") | G25: "Tecelagem piquê (interlock com relevo micro-mesh)" — piquê é malha de ponto carregado, não interlock nem tecelagem | H25: 240 g/m² (± 5%) | I25: 51% poliéster + 49% algodão (poliéster majoritário) | J25: 3 | K25: =P22!$B$62 | L25: =P22!E64 | M25: =P22!D68 | N25: =P22!B74 | O25: =P22!B75 | P25: =P22!B78 | Q25: Composição: 51% poliéster / 49% algodão — confirma o texto do P05; o texto do P04 (52% algodão / 48% poliéster) vale para Rib Wide, Plissé, Ripple e Waffle, não para a Piqué. São duas composições na mesma "linha texturizada".
A26: P23 | B26: Regata | C26: HMZT-P23-SLM-CAN21 | D26: Regata Masculina Canelada 2/1 Slim Fit (American Style) | E26: Regatas / Verão — Essencial (entrada, kit e cross-sell) | F26: Slim fit / American style (ajustada) | G26: Canelada rib knit 2/1, 'alta densidade de fios' | H26: Não informada | I26: 100% algodão (sem elastano — elasticidade é mecânica, da nervura) | J26: 5 | K26: =P23!$B$58 | L26: =P23!E60 | M26: =P23!D64 | N26: =P23!B70 | O26: =P23!B71 | P26: =P23!B74 | Q26: Estoque: página diz 'Esse acabou' (nenhuma variação selecionável); resumo diz 'Envio em até 24h'.
A27: P24 | B27: Regata | C27: HMZT-P24-SLM-CAN21SW | D27: Regata Estonada Canelada 2/1 Slim Fit (Stone Wash) | E27: Regatas / Verão — Vintage (drop streetwear, lavada) | F27: Slim fit atlético | G27: Canelada rib knit 2/1 (mesma base da P23) | H27: Não informada | I27: 100% algodão | J27: 4 | K27: =P24!$B$60 | L27: =P24!E62 | M27: =P24!D66 | N27: =P24!B72 | O27: =P24!B73 | P27: =P24!B76 | Q27: Preço invertido: a estonada (R$ 23,99) custa MENOS que a lisa P23 (R$ 24,99), apesar de ter uma etapa extra de lavanderia.
A28: P25 | B28: Calça | C28: HMZT-P25-CNF-MOL320 | D28: Calça Moletom 3 Cabos 320g Felpada Confort Fit | E28: Inverno Heavy — conjunto com o moletom P26 (calça avulsa como complemento) | F28: Confort fit 'levemente solta' — nas fotos: jogger com perna afunilada | G28: Moletom 3 cabos (triple ply) com felpado interno | H28: 320 g/m² (heavyweight) | I28: 50% algodão + 50% poliéster | J28: 4 | K28: =P25!$B$60 | L28: =P25!E62 | M28: =P25!D66 | N28: =P25!B72 | O28: =P25!B73 | P28: =P25!B76 | Q28: Estoque: 'Disponibilidade: Imediata' + 'Esse acabou' na mesma página.
A29: P26 | B29: Moletom | C29: HMZT-P26-REG-MOL320 | D29: Moletom Gola Careca 3 Cabos 320g Felpado | E29: Inverno Heavy — moletom 320g (topo do inverno; conjunto com a calça P25) | F29: Regular fit, sem capuz e sem bolso | G29: Moletom 3 cabos (triple ply) com felpado interno | H29: 320 g/m² (heavyweight) | I29: 50% algodão + 50% poliéster | J29: 6 | K29: =P26!$B$63 | L29: =P26!E65 | M29: =P26!D69 | N29: =P26!B75 | O29: =P26!B76 | P29: =P26!B79 | Q29: Preço: a página mostra R$ 68,00 no seletor; o texto dá preço base de R$ 59,00 e tabela a partir dele. Provável preço de varejo/unidade × atacado — confirmar qual vale no pedido.
A30: P27 | B30: Manga longa | C30: HMZT-P27-RGL-ML300 | D30: Blusa Raglan Manga Longa 300g (fio importado 2 cabos) | E30: Meia-estação — Manga longa 'Design' (raglan) · condicionada à composição | F30: Regular fit, manga longa raglan | G30: Malha 2 cabos (double ply), sem peluciado; interior liso | H30: 300 g/m² | I30: 'Fio importado chinês de fibra longa' — SEM percentual | J30: 4 | K30: =P27!$B$58 | L30: =P27!E60 | M30: =P27!D64 | N30: =P27!B70 | O30: =P27!B71 | P30: =P27!B74 | Q30: Composição não informada em % — só 'fio importado chinês'. Não dá para etiquetar (rotulagem têxtil exige composição) nem afirmar 'algodão'.
A31: P28 | B31: Moletom | C31: HMZT-P28-REG-PEL260 | D31: Moletom Canguru Peluciado 260g com Capuz e Cordão | E31: Inverno — Hoodie (moletom canguru, peça de desejo) | F31: Regular fit com capuz | G31: Moletinho 2 cabos com peluciado interno (escovado) | H31: 260 g/m² (texto) · ⚠️ arquivos das fotos: '240gsm' | I31: 50% algodão + 50% poliéster | J31: 5 | K31: =P28!$B$62 | L31: =P28!E64 | M31: =P28!D68 | N31: =P28!B74 | O31: =P28!B75 | P31: =P28!B78 | Q31: Gramatura: página e ficha dizem 260 g; TODOS os 15 arquivos de foto se chamam 'moletom_canguru_2_cabos_basico_240gsm'. Ou a foto é de outro produto (240 g, 'básico'), ou a gramatura mudou.
A32: P29 | B32: Manga longa | C32: HMZT-P29-REG-ML300 | D32: Blusa Manga Longa Gola Careca 300g (fio importado 2 cabos) | E32: Meia-estação — Manga longa clássica · condicionada à composição | F32: Regular fit, manga longa set-in | G32: Malha 2 cabos (double ply), sem peluciado; interior liso | H32: 300 g/m² | I32: 'Fio importado chinês de fibra longa' — SEM percentual | J32: 4 | K32: =P29!$B$59 | L32: =P29!E61 | M32: =P29!D65 | N32: =P29!B71 | O32: =P29!B72 | P32: =P29!B75 | Q32: Composição não informada em % — só 'fio importado chinês de fibra longa'. Não dá para etiquetar nem afirmar 'algodão'.
A34: Valores em verde vêm das abas de cada produto. Custo e preço de venda são estimativas até chegarem os orçamentos.

Sheet Regras Fornecedor
A1: Regras gerais — Lunfe Malhas (fabricação própria, Itajaí-SC)
A3: Faixa | B3: De (pç) | C3: Até (pç) | D3: Desconto
A4: Faixa 1 | B4: 20 | C4: 40 | D4: 0.1
A5: Faixa 2 | B5: 40 | C5: 80 | D5: 0.15
A6: Faixa 3 | B6: 80 | C6: 100 | D6: 0.2
A7: Faixa 4 | B7: 100 | C7: 300 | D7: 0.25
A8: Faixa 5 | B8: 300 | C8: 999 | D8: 0.3
A10: Desconto Pix adicional | B10: 0.05 | C10: Sobre o preço já com desconto progressivo
A11: Pedido mínimo (pç, pedido total) | B11: 20
A13: Outras condições
A14: Cartão | B14: Até 6× sem juros no atacado (página do produto diz "com juros" ⚠️ — confirmar)
A15: Boleto | B15: 30/60 dias para cadastro aprovado acima de R$ 2.000
A16: Amostra | B16: Até 2 peças, cobradas e abatidas no pedido aprovado; frete por conta do cliente
A17: Mistura | B17: Mínimo de 20 peças no pedido total — mistura livre de produtos, modelos, cores e tamanhos; soma para o desconto
A18: Cor Pantone exclusiva | B18: A partir de 100 peças/cor; 15–25 dias úteis
A19: Embalagem customizada | B19: A partir de 50 peças
A20: Personalização | B20: Silk, DTF, bordado, private label a partir de 20 peças — preço SEMPRE sob orçamento
A21: Prazo | B21: Lisas em estoque: despacho em 24h úteis · personalizadas: sob consulta
A22: Grade customizada | B22: Acima de 200 peças (sob consulta)
A23: Molde regular | B23: Tabela única em todos os regulares: M = 72 × 54 cm, ombro 46, manga 18; P–EG, +2 cm por tamanho
A24: Modelo das fotos | B24: 1,84 m · 84 kg · veste M
A25: Nota fiscal | B25: NF-e com CFOP de revenda; Simples, Presumido e Real
A26: Fabricação | B26: Própria: tecelagem, tingimento, corte, confecção e tratamentos em Itajaí-SC

Sheet P01
A1: P01 — Camiseta Oversized Suedine Peruano 300g
A3: 1. Identificação
A4: Código HMZT | B4: HMZT-P01-OVS-SUE300
A5: Fornecedor | B5: Lunfe Malhas — fabricação própria, Itajaí-SC
A6: Referência | B6: 7897385478523 (EAN-13)
A7: URL | B7: lunfemalhas.com.br/camiseta-oversized-suedine-peruano-300g-atacado-lunfe
A8: Categoria no site | B8: Camisetas › Masculino › Oversized
A9: Linha HMZT recomendada | B9: Heavy (oversized)
A10: Estoque | B10: Em estoque
A11: Descritor canônico (IA) | B11: Camiseta masculina heavyweight oversized boxy, ombro caído, manga larga até acima do cotovelo, gola careca canelada, malha aveludada e fosca tipo camurça.
A13: 2. Especificação técnica
A14: Item | B14: Valor | C14: Fonte
A15: Modelagem | B15: Oversized boxy, ombro caído (drop shoulder)
A16: Gramatura | B16: 300 g/m² (heavyweight)
A17: Tecido | B17: Suedine — acabamento escovado (peach finish), toque de camurça
A18: Composição | B18: 52% algodão / 48% poliéster
A19: Gola | B19: Careca, ribana canelada média
A20: Manga | B20: Curta, larga, até acima do cotovelo
A21: Barra | B21: Reta, pouco abaixo do quadril
A22: Opacidade | B22: Total (mesma malha do P04)
A23: Irmão | B23: P04 — mesma malha, modelagem regular (texto do P04 confirma)
A24: Cuidados | B24: Lavar do avesso a 30 °C, sem secadora quente, não passar ferro direto na superfície
A26: 3. Tabela de medidas (cm)
A27: ⚠️ Tabela da oversized NÃO informada — pedir ao fornecedor (referência provisória: Chinese Heavyweight oversized, aba P05).
A28: Modelo das fotos: 1,84 m · 84 kg · veste M
A30: 4. Cores disponíveis
A31: Cor | B31: Código HMZT | C31: Ref. fornecedor | D31: Observação
A32: Off-white | B32: OFF | C32: — | D32: Cor das fotos
A33: Areia / bege | B33: ARE | C33: —
A34: Cinza chumbo | B34: CHU | C34: —
A35: ⚠️ Cartela da página. O texto do P04 (mesma malha) lista Preto, Off White, Bege, Marrom, Marinho (refs SDP-). Confirmar a cartela da oversized.
A37: 5. Personalização (preço sempre sob orçamento)
A38: Técnica | B38: Detalhe | C38: Mínimo
A39: Silk base d'água | B39: Testar aderência sobre suedine | C39: 20 pç
A40: DTF | B40: Testar aderência | C40: 20 pç
A41: Bordado | B41: Melhor resultado; costas na oversized | C41: 20 pç
A42: Etiqueta private label | B42: Interna + tag | C42: 20 pç
A43: Embalagem customizada | C43: 50 pç
A44: Cor Pantone | C44: 100 pç/cor
A46: 6. Preços do fornecedor (desconto progressivo)
...

Sheet P02
A1: P02 — Camiseta Oversized Drop Shoulder Algodão Penteado 185g
A3: 1. Identificação
A4: Código HMZT | B4: HMZT-P02-OVS-ALG185
A5: Fornecedor | B5: Lunfe Malhas — fabricação própria, Itajaí-SC
A6: Referência | B6: 7899196241006
A7: URL | B7: lunfemalhas.com.br/camiseta-oversized-drop-shoulder-atacado-185g-lunfe
A8: Categoria no site | B8: Camisetas › Masculino › Oversized
A9: Linha HMZT recomendada | B9: Essencial — oversized (drops com estampa, eventos)
A10: Estoque | B10: Disponibilidade imediata; 2 cores; despacho em 24h úteis
A11: Descritor canônico (IA) | B11: Camiseta masculina oversized drop shoulder, manga curta larga até acima do cotovelo, ombro caído cerca de 2 cm além do ombro, gola careca canelada fina, meia malha 100% algodão penteado de 185 g/m² com superfície lisa e fosca, caimento amplo e leve com dobras suaves, barra dupla reta abaixo do quadril. Peça lisa, sem logos. Fundo cinza claro de estúdio.
A13: 2. Especificação técnica
A14: Item | B14: Valor | C14: Fonte
A15: Composição | B15: 100% algodão penteado
A16: Gramatura | B16: 185 g/m² (resumo do topo diz 300 g/m²)
A17: Tecido | B17: Meia malha lisa, sem acabamento especial
A18: Modelagem | B18: Oversized drop shoulder — ombro caído, corpo amplo, comprimento alongado
A19: Gola | B19: Canelada 2/1, fecho em anel, reforço ombro a ombro
A20: Costuras | B20: Ponto cadeia em todas as emendas
A21: Barras | B21: Dupla nas mangas e na barra inferior
A22: Tratamentos | B22: Pré-encolhimento mecânico, tingimento reativo, anti-torção, amaciamento
A23: Tamanhos | B23: P, M, G, GG, EG (grade oversized)
A24: Queda do ombro | B24: Texto: 4–8 cm abaixo do ombro; tabela: só +2 cm por lado
A25: Giro | B25: 'A oversized mais vendida', 'maior giro do catálogo'
A26: Produção | B26: Fabricação própria — Itajaí, SC
A28: 3. Tabela de medidas (cm)
A29: Tabela 1
A30: Tamanho | B30: Comprimento | C30: Largura | D30: Ombros | E30: Mangas
A31: P | B31: 74 | C31: 56 | D31: 48 | E31: 20
A32: M | B32: 76 | C32: 58 | D32: 50 | E32: 22
A33: G | B33: 78 | C33: 60 | D33: 52 | E33: 24
A34: GG | B34: 80 | C34: 62 | D34: 54 | E34: 26
A35: EG | B35: 82 | C35: 64 | D35: 56 | E35: 28
A36: Regular Lunfe (comparação)
A37: Tamanho | B37: Comprimento | C37: Largura | D37: Ombros | E37: Mangas
A38: P | B38: 70 | C38: 52 | D38: 44 | E38: 16
A39: M | B39: 72 | C39: 54 | D39: 46 | E39: 18
A40: G | B40: 74 | C40: 56 | D40: 48 | E40: 20
A41: GG | B41: 76 | C41: 58 | D41: 50 | E41: 22
A42: EG | B42: 78 | C42: 60 | D42: 52 | E42: 24
A43: Grade oversized oficial, em cm, ± 2 cm. M oversized = regular +4 cm em todas as medidas. Modelo 1,84 m / 84 kg veste M. Única tabela oversized publicada — referência provisória para P01 e P10.
...

Sheet P03
A1: P03 — Camiseta Pima Cotton 165g
A3: 1. Identificação
A4: Código HMZT | B4: HMZT-P03-REG-PIM165
A5: Fornecedor | B5: Lunfe Malhas — fabricação própria, Itajaí-SC
A6: Referência | B6: cms-pimacotton (código interno)
A7: URL | B7: lunfemalhas.com.br/camiseta-pima-cotton-165g-100-algodao-puro-atacado-lunfe
A8: Categoria no site | B8: Camisetas › Masculino › Premium
A9: Linha HMZT recomendada | B9: Premium (principal)
A10: Estoque | B10: 8 cores em estoque (página mostra 5 ⚠️)
A11: Descritor canônico (IA) | B11: Camiseta masculina regular fit, manga ajustada até metade do bíceps, gola careca de ribana fina rente, malha leve de algodão sedosa com brilho natural.
A13: 2. Especificação técnica
A14: Item | B14: Valor | C14: Fonte
A15: Composição | B15: 100% algodão Pima (G. barbadense) — sem elastano, sem poliéster
A16: Fibra | B16: Extra-longa, staple > 35 mm
A17: Construção | B17: "Malha premium" — título do fio não informado
A18: Gramatura | B18: 165 g/m²
A19: Modelagem | B19: Regular fit
A20: Gola | B20: Careca, ribana reforçada
A21: Mangas | B21: Curtas, barra dupla
A22: Barra | B22: Dupla, acabamento invisível
A23: Costuras | B23: Reforçadas; ombro a ombro com fita interna
A24: Tratamentos | B24: Pré-encolhimento industrial; fixação de cor de alta solidez
A25: Encolhimento | B25: 1–2% nas primeiras lavagens, estabiliza após 2–3 ciclos
A26: Cuidados | B26: Lavar a 30 °C, sem secadora quente, pendurar; ferro baixo
A27: Produção | B27: Própria Lunfe — Itajaí-SC
A29: 3. Tabela de medidas (cm)
A30: Tamanho | B30: Comprimento | C30: Largura | D30: Ombros | E30: Mangas
A31: P | B31: 70 | C31: 52 | D31: 44 | E31: 16
A32: M | B32: 72 | C32: 54 | D32: 46 | E32: 18
A33: G | B33: 74 | C33: 56 | D33: 48 | E33: 20
A34: GG | B34: 76 | C34: 58 | D34: 50 | E34: 22
A35: EG | B35: 78 | C35: 60 | D35: 52 | E35: 24
A36: Em cm, em repouso, ± 2 cm. Molde regular padrão.
A37: Modelo das fotos: 1,84 m · 84 kg · veste M
A39: 4. Cores disponíveis
A40: Cor | B40: Código HMZT | C40: Ref. fornecedor | D40: Observação
A41: Preto | B41: PRT | C41: PMA-PRT | D41: Não aparecia no seletor
A42: Off White | B42: OFF | C42: PMA-OFW | D42: Não aparecia no seletor
A43: Bege | B43: BGE | C43: PMA-BGE | D43: Provável "creme"
A44: Capuccino | B44: CAP | C44: PMA-CAP | D44: Exclusiva do Pima; provável "caramelo"
...

Sheet P04
A1: P04 — Camiseta Suedine Peruano 300g Regular Fit
A3: 1. Identificação
A4: Código HMZT | B4: HMZT-P04-REG-SUE300
A5: Fornecedor | B5: Lunfe Malhas — fabricação própria, Itajaí-SC
A6: Referência | B6: 7891865209942 (EAN-13)
A7: URL | B7: lunfemalhas.com.br/camiseta-suedine-peruano-300g-toque-aveludado-atacado-lunfe
A8: Categoria no site | B8: Algodão Importado (breadcrumb) · também em Masculino › Premium
A9: Linha HMZT recomendada | B9: Heavy (principal)
A10: Estoque | B10: 5 cores em estoque
A11: Descritor canônico (IA) | B11: Camiseta masculina heavyweight regular fit, manga reta, gola careca canelada, malha encorpada aveludada e fosca tipo camurça, caimento estruturado.
A13: 2. Especificação técnica
A14: Item | B14: Valor | C14: Fonte
A15: Composição | B15: 52% algodão / 48% poliéster
A16: Acabamento | B16: Suedine (peach/sanded finish) — escovação com micro-abrasivos; físico, permanente
A17: Gramatura | B17: 300 g/m²
A18: Modelagem | B18: Regular fit, caimento estruturado sem elastano
A19: Gola | B19: Careca, ribana reforçada
A20: Mangas | B20: Curtas, barra dupla
A21: Barra | B21: Dupla, acabamento invisível
A22: Costuras | B22: Reforçadas; ombro a ombro com fita interna
A23: Tratamentos | B23: Pré-encolhimento industrial; fixação de cor
A24: Opacidade | B24: Total, inclusive off white
A25: Cuidados | B25: Lavar do avesso a 30 °C, sem secadora quente, não passar ferro direto
A26: Uso | B26: Meia-estação 15–22 °C; mar–out no Sul/Sudeste
A28: 3. Tabela de medidas (cm)
A29: Tamanho | B29: Comprimento | C29: Largura | D29: Ombros | E29: Mangas
A30: P | B30: 70 | C30: 52 | D30: 44 | E30: 16
A31: M | B31: 72 | C31: 54 | D31: 46 | E31: 18
A32: G | B32: 74 | C32: 56 | D32: 48 | E32: 20
A33: GG | B33: 76 | C33: 58 | D33: 50 | E33: 22
A34: EG | B34: 78 | C34: 60 | D34: 52 | E34: 24
A35: Em cm, em repouso, ± 2 cm.
A36: Modelo das fotos: 1,84 m · 84 kg · veste M
A38: 4. Cores disponíveis
A39: Cor | B39: Código HMZT | C39: Ref. fornecedor | D39: Observação
A40: Preto | B40: PRT | C40: SDP-PRT
A41: Off White | B41: OFF | C41: SDP-OFW | D41: 100% opaco
A42: Bege | B42: BGE | C42: SDP-BGE | D42: Provável nude/rosé das fotos
A43: Marrom | B43: MRR | C43: SDP-MRR | D43: "A que mais parece camurça"
A44: Marinho | B44: MAR | C44: SDP-MRN
...

Sheet P05
A1: P05 — Camiseta Chinese Heavyweight 300g
A3: 1. Identificação
A4: Código HMZT | B4: HMZT-P05-REG-XJG300 / -OVS-
A5: Fornecedor | B5: Lunfe Malhas — fabricação própria, Itajaí-SC
A6: Referência | B6: 790836512100 (12 dígitos ⚠️)
A7: URL | B7: lunfemalhas.com.br/camiseta-chinese-heavyweight-atacado-300g-algodao-importado-lunfe
A8: Categoria no site | B8: Camisetas › Masculino › Premium
A9: Linha HMZT recomendada | B9: Heavy (alternativa ⚠️ Xinjiang)
A10: Estoque | B10: 4 cores em pronta entrega permanente
A11: Descritor canônico (IA) | B11: Camiseta masculina heavyweight regular, gola careca estruturada, malha de algodão grossa e encorpada com leve brilho acetinado, caimento reto.
A13: 2. Especificação técnica
A14: Item | B14: Valor | C14: Fonte
A15: Composição | B15: 100% algodão importado — origem Xinjiang, China ⚠️
A16: Fibra | B16: Longa, staple 28–30 mm
A17: Fio | B17: 28/1 × 2 cabos (retorcido duplo; equivale a ~14/1)
A18: Gramatura | B18: 300 g/m² ± 5% ("ultra-heavyweight")
A19: Rolo / rendimento | B19: 1,80 m tubular aberta · 3,0–3,5 camisetas/m (M)
A20: Modelagens | B20: Regular (P–GG) + Oversized (P–G1) — mesma malha
A21: Gola | B21: Canelada 2/1 estruturada, fecho em anel
A22: Ombros | B22: Reforço ombro a ombro com faixa larga
A23: Costuras | B23: Ponto cadeia
A24: Barras | B24: Dupla nas mangas e barra
A25: Tratamentos | B25: Pré-encolhimento (<3%), tingimento reativo, anti-torção, amaciamento, anti-pilling enzimático
A26: Anti-rugas | B26: Não
A27: Versão feminina | B27: Não existe (em análise)
A29: 3. Tabela de medidas (cm)
A30: Regular
A31: Tamanho | B31: Comprimento | C31: Largura | D31: Ombros | E31: Mangas
A32: P | B32: 70 | C32: 52 | D32: 44 | E32: 16
A33: M | B33: 72 | C33: 54 | D33: 46 | E33: 18
A34: G | B34: 74 | C34: 56 | D34: 48 | E34: 20
A35: GG | B35: 76 | C35: 58 | D35: 50 | E35: 22
A36: Oversized
A37: Tamanho | B37: Comprimento | C37: Largura | D37: Ombros | E37: Mangas
A38: P | B38: 74 | C38: 57 | D38: 54 | E38: 24
A39: M | B39: 76 | C39: 59 | D39: 56 | E39: 25
A40: G | B40: 78 | C40: 61 | D40: 58 | E40: 26
A41: GG | B41: 80 | C41: 64 | D41: 60 | E41: 27
A42: G1 | B42: 82 | C42: 67 | D42: 62 | E42: 28
A43: Regular vai só até GG (sem EG ⚠️). ± 2 cm.
...

Sheet P06
A1: P06 — Camiseta Chinese Cotton 160g
A3: 1. Identificação
A4: Código HMZT | B4: HMZT-P06-REG-XJG160
A5: Fornecedor | B5: Lunfe Malhas — fabricação própria, Itajaí-SC
A6: Referência | B6: 7908365128857 (EAN-13)
A7: URL | B7: lunfemalhas.com.br/camiseta-chinese-cotton-atacado-lunfe
A8: Categoria no site | B8: Camisetas › Masculino › Premium
A9: Linha HMZT recomendada | B9: Essencial (alternativa ⚠️ Xinjiang)
A10: Estoque | B10: 5 cores em pronta entrega permanente
A11: Descritor canônico (IA) | B11: Camiseta masculina regular fit, gola careca canelada fina, malha leve de algodão penteado com leve brilho acetinado.
A13: 2. Especificação técnica
A14: Item | B14: Valor | C14: Fonte
A15: Composição | B15: 100% algodão importado — Xinjiang, China ⚠️
A16: Fibra | B16: Longa, staple 28–30 mm
A17: Fio | B17: Penteado, 30/1
A18: Gramatura | B18: 160 g/m² ± 5% (⚠️ texto do P05 diz 180g)
A19: Rolo / rendimento | B19: 1,80 m tubular aberta · 4,0–4,5 camisetas/m (M)
A20: Modelagem | B20: Regular fit
A21: Gola | B21: Canelada 2/1, fecho em anel (sem emenda frontal)
A22: Ombros | B22: Reforço ombro a ombro
A23: Costuras | B23: Ponto cadeia
A24: Barras | B24: Dupla nas mangas e barra
A25: Tratamentos | B25: Pré-encolhimento (<3%), tingimento reativo, anti-torção, anti-pilling enzimático, amaciamento
A27: 3. Tabela de medidas (cm)
A28: Tamanho | B28: Comprimento | C28: Largura | D28: Ombros | E28: Mangas
A29: P | B29: 70 | C29: 52 | D29: 44 | E29: 16
A30: M | B30: 72 | C30: 54 | D30: 46 | E30: 18
A31: G | B31: 74 | C31: 56 | D31: 48 | E31: 20
A32: GG | B32: 76 | C32: 58 | D32: 50 | E32: 22
A33: EG | B33: 78 | C33: 60 | D33: 52 | E33: 24
A34: ± 2 cm. Grade customizada acima de 200 pç.
A35: Modelo das fotos: 1,84 m · 84 kg · veste M
A37: 4. Cores disponíveis
A38: Cor | B38: Código HMZT | C38: Ref. fornecedor | D38: Observação
A39: Preto | B39: PRT | C39: CHC-PRT | D39: Maior giro
A40: Marinho | B40: MAR | C40: CHC-MRN | D40: 2º maior giro
A41: Verde Militar | B41: VML | C41: CHC-VML
A42: Azul Celeste | B42: AZC | C42: CHC-AZC
A43: Off White | B43: OFF | C43: CHC-OFW | D43: Cor das fotos
A44: Pantone a partir de 100 pç/cor.
...

Sheet P07
A1: P07 — Camiseta Cotton Peruano 220g com Elastano
A3: 1. Identificação
A4: Código HMZT | B4: HMZT-P07-REG-PER220
A5: Fornecedor | B5: Lunfe Malhas — fabricação própria, Itajaí-SC
A6: Referência | B6: 7892474270330 (EAN-13)
A7: URL | B7: lunfemalhas.com.br/camiseta-cotton-peruano-220g-elastano-atacado-lunfe
A8: Categoria no site | B8: Camisetas › Masculino › Premium
A9: Linha HMZT recomendada | B9: Premium (alternativa)
A10: Estoque | B10: 🔴 Página: "Esse acabou" × texto: 6 cores em estoque
A11: Descritor canônico (IA) | B11: Camiseta masculina regular fit, gola careca de ribana fina, jersey de algodão com leve brilho acetinado que acompanha o corpo.
A13: 2. Especificação técnica
A14: Item | B14: Valor | C14: Fonte
A15: Composição | B15: 96% algodão peruano (G. barbadense) + 4% elastano
A16: Fibra | B16: Extra-longa, staple > 34 mm (Pima peruano ou Tangüis?)
A17: Construção | B17: Jersey 30/1
A18: Gramatura | B18: 220 g/m²
A19: Modelagem | B19: Regular fit
A20: Gola | B20: Careca, ribana reforçada
A21: Mangas | B21: Curtas, barra dupla
A22: Barra | B22: Dupla, acabamento invisível
A23: Costuras | B23: Reforçadas; ombro a ombro com fita
A24: Tratamentos | B24: Pré-encolhimento; fixação de cor de alta solidez
A25: Elastano | B25: Memória de forma, caimento, menos rugas
A26: Opacidade | B26: Opaca em todas as cores
A28: 3. Tabela de medidas (cm)
A29: Tamanho | B29: Comprimento | C29: Largura | D29: Ombros | E29: Mangas
A30: P | B30: 70 | C30: 52 | D30: 44 | E30: 16
A31: M | B31: 72 | C31: 54 | D31: 46 | E31: 18
A32: G | B32: 74 | C32: 56 | D32: 48 | E32: 20
A33: GG | B33: 76 | C33: 58 | D33: 50 | E33: 22
A34: EG | B34: 78 | C34: 60 | D34: 52 | E34: 24
A35: Em cm, em repouso, ± 2 cm.
A36: Modelo das fotos: 1,84 m · 84 kg · veste M
A38: 4. Cores disponíveis
A39: Cor | B39: Código HMZT | C39: Ref. fornecedor | D39: Observação
A40: Preto | B40: PRT | C40: CPR-PRT | D40: Cor das fotos
A41: Off White | B41: OFF | C41: CPR-OFW
A42: Bege | B42: BGE | C42: CPR-BGE | D42: Provável nude da 5ª foto
A43: Marinho | B43: MAR | C43: CPR-MRN
A44: Bordô | B44: BDO | C44: CPR-BDO
...

Sheet P08
A1: P08 — Camiseta Egyptian Cotton Fio 50/1 com Elastano
A3: 1. Identificação
A4: Código HMZT | B4: HMZT-P08-REG-EGY50
A5: Fornecedor | B5: Lunfe Malhas — fabricação própria, Itajaí-SC
A6: Referência | B6: 7891557272995 (EAN-13)
A7: URL | B7: lunfemalhas.com.br/camiseta-egyptian-cotton-atacado-algodao-egipcio-50-1-lunfe
A8: Categoria no site | B8: Camisetas › Masculino › Premium
A9: Linha HMZT recomendada | B9: Topo / Assinatura (inclui unissex)
A10: Estoque | B10: 7 cores em estoque (off white com traço na página ⚠️)
A11: Descritor canônico (IA) | B11: Camiseta regular fit de caimento fluido, gola careca de ribana lisa fina, malha leve de algodão muito lisa com brilho natural sutil.
A13: 2. Especificação técnica
A14: Item | B14: Valor | C14: Fonte
A15: Composição | B15: 91,5% algodão egípcio (G. barbadense) + 8,5% elastano
A16: Fibra | B16: Extra-longa, staple 32–36 mm
A17: Fio | B17: Penteado e refinado 50/1 (o mais fino do catálogo)
A18: Gramatura | B18: 170 g/m²
A19: Modelagem | B19: Regular fit, caimento fluido
A20: Gola | B20: Ribana 2/1 lisa (sem canelado)
A21: Costura interna | B21: Ponto conjugado (costura plana)
A22: Ombros | B22: Reforço ombro a ombro
A23: Barra | B23: Dupla
A24: Tratamentos | B24: Pré-encolhimento, fixação reativa de cor, amaciamento
A25: Certificação | B25: OEKO-TEX Standard 100 (algodão e elastano)
A27: 3. Tabela de medidas (cm)
A28: Tamanho | B28: Comprimento | C28: Largura | D28: Ombros | E28: Mangas
A29: P | B29: 70 | C29: 52 | D29: 44 | E29: 16
A30: M | B30: 72 | C30: 54 | D30: 46 | E30: 18
A31: G | B31: 74 | C31: 56 | D31: 48 | E31: 20
A32: GG | B32: 76 | C32: 58 | D32: 50 | E32: 22
A33: EG | B33: 78 | C33: 60 | D33: 52 | E33: 24
A34: Em cm, em repouso, ± 2 cm.
A35: Modelo das fotos: 1,84 m · 84 kg · veste M
A37: 4. Cores disponíveis
A38: Cor | B38: Código HMZT | C38: Ref. fornecedor | D38: Observação
A39: Off White | B39: OFF | C39: EGY-OFW | D39: Traço na bolinha — confirmar estoque
A40: Bordô | B40: BDO | C40: EGY-BRD
A41: Bege | B41: BGE | C41: EGY-BGE | D41: 7ª cor que faltava no seletor
A42: Preto | B42: PRT | C42: EGY-PRT
A43: Verde Militar | B43: VML | C43: EGY-VML
A44: Laranja | B44: LAR | C44: EGY-LRJ
...

Sheet P09
A1: P09 — Camiseta Suedine Light
A3: 1. Identificação
A4: Código HMZT | B4: HMZT-P09-REG-SUELT
A5: Fornecedor | B5: Lunfe Malhas — fabricação própria, Itajaí-SC
A6: Referência | B6: 7908365128002 (EAN-13)
A7: URL | B7: lunfemalhas.com.br/camiseta-suedine-light-atacado-toque-aveludado-lunfe
A8: Categoria no site | B8: Camisetas › Masculino › Premium
A9: Linha HMZT recomendada | B9: Suedine light
A10: Estoque | B10: Lisas em estoque, 24h
A11: Descritor canônico (IA) | B11: Camiseta masculina regular fit, gola careca canelada, malha leve aveludada e fosca, caimento reto e fluido.
A13: 2. Especificação técnica
A14: Item | B14: Valor | C14: Fonte
A15: Composição | B15: Blend algodão + fibras sintéticas — % NÃO informado
A16: Gramatura | B16: "Leve" — número NÃO informado
A17: Acabamento | B17: Suedine aveludado
A18: Modelagem | B18: Regular fit, caimento fluido
A19: Gola | B19: Careca
A20: Acabamentos | B20: Costuras reforçadas, pré-encolhida
A21: Uso | B21: Ano inteiro; segunda pele sob jaqueta
A23: 3. Tabela de medidas (cm)
A24: Tamanho | B24: Comprimento | C24: Largura | D24: Ombros | E24: Mangas
A25: P | B25: 70 | C25: 52 | D25: 44 | E25: 16
A26: M | B26: 72 | C26: 54 | D26: 46 | E26: 18
A27: G | B27: 74 | C27: 56 | D27: 48 | E27: 20
A28: GG | B28: 76 | C28: 58 | D28: 50 | E28: 22
A29: EG | B29: 78 | C29: 60 | D29: 52 | E29: 24
A30: Em cm, variação 1–2 cm.
A31: Modelo das fotos: 1,84 m · 84 kg · veste M
A33: 4. Cores disponíveis
A34: Cor | B34: Código HMZT | C34: Ref. fornecedor | D34: Observação
A35: Bege | B35: BGE | C35: — | D35: ⚠️ Fotos em caramelo — é este?
A36: Preto | B36: PRT | C36: —
A37: Azul Bebê | B37: AZB | C37: —
A38: Laranja | B38: LAR | C38: —
A39: Verde | B39: VRD | C39: —
A40: Mockup do fornecedor mostra off white (fora da lista). Sem códigos de referência.
A42: 5. Personalização (preço sempre sob orçamento)
A43: Técnica | B43: Detalhe | C43: Mínimo
A44: Silk | B44: Testar aderência | C44: 20 pç?
A45: DTF | B45: Testar aderência | C45: 20 pç?
...

Sheet P10
A1: P10 — Camiseta Oversized Básica Suedine 300GSM (100% algodão)
A3: 1. Identificação
A4: Código HMZT | B4: HMZT-P10-OVS-SUEALG300
A5: Fornecedor | B5: Lunfe Malhas — fabricação própria, Itajaí-SC
A6: Referência | B6: 7896630253786
A7: URL | B7: lunfemalhas.com.br/camiseta-oversized-basica-lunfe-399
A8: Categoria no site | B8: Camisetas › Masculino › Oversized
A9: Linha HMZT recomendada | B9: Heavy — oversized (alternativa mais barata à P01)
A10: Estoque | B10: 6 cores no seletor; sem campo de disponibilidade; texto diz 'estoque limitado'
A11: Descritor canônico (IA) | B11: Camiseta masculina oversized boxy heavyweight, ombro bem caído no braço, manga curta larga até o cotovelo, gola careca de ribana canelada larga (2,5 cm), malha encorpada de 300 g/m² com superfície fosca e macia, corpo amplo e quadrado que se sustenta, barra reta abaixo do quadril. Peça lisa, sem logos. Fundo cinza claro de estúdio.
A13: 2. Especificação técnica
A14: Item | B14: Valor | C14: Fonte
A15: Tecido | B15: Malha suedine 'interlock de dupla frontura'
A16: Composição | B16: 100% algodão (P01, também suedine 300g, é 52/48)
A17: Gramatura | B17: 300 g/m², zero transparência
A18: Toque | B18: 'Aveludado / pele de pêssego' e 'acetinado' na mesma página
A19: Gola | B19: Ribana canelada 2,5 cm, alta densidade
A20: Reforço | B20: Ombro a ombro
A21: Modelagem | B21: True oversized boxy, ombros caídos
A22: Tamanhos | B22: Não informados
A23: Autoridade | B23: 'Elimina qualquer objeção de preço', 'vicia o cliente'
A24: Produção | B24: Fabricação própria — Itajaí, SC
A26: 3. Tabela de medidas (cm)
A27: ⚠️ Tabela de medidas não publicada. Modelo 1,84 m / 84 kg veste M. Pelas fotos é mais boxy que a P02 (ombro 6–8 cm no braço, manga no cotovelo). Não publicar medidas sem a tabela oficial.
A28: Modelo das fotos: 1,84 m · 84 kg · veste M
A30: 4. Cores disponíveis
A31: Cor | B31: Código HMZT | C31: Ref. fornecedor | D31: Observação
A32: Preto | B32: PRT | C32: — | D32: Fotos #14–15
A33: Branco | B33: BCO | C33: — | D33: Fotos #5–8
A34: Cinza | B34: CZA | C34: — | D34: Cinza médio/chumbo, fotos #1–4
A35: Bege | B35: BGE | C35: — | D35: Sem foto
A36: Azul Marinho | B36: MAR | C36: — | D36: Sem foto
A37: Rose Gold | B37: RSG | C37: — | D37: Rosé empoeirado, fotos #9–13
A38: 6 cores; fornecedor não publica refs. de cor nesta página. Bege e Azul Marinho sem foto.
A40: 5. Personalização (preço sempre sob orçamento)
A41: Técnica | B41: Detalhe | C41: Mínimo
A42: Bordado | B42: Peito ou costas — melhor contraste sobre superfície escovada | C42: 20 pç
A43: DTF | B43: Full color — peça-teste de aderência | C43: 20 pç
A44: Silk base d'água | B44: Testar sobre o felpado | C44: 20 pç
A45: Etiqueta private label | B45: Interna + tag | C45: 20 pç
...

Sheet P11
A1: P11 — Camiseta Custo Inteligente Malha Algodão/Poliéster 160g
A3: 1. Identificação
A4: Código HMZT | B4: HMZT-P11-REG-PA160
A5: Fornecedor | B5: Lunfe Malhas — fabricação própria, Itajaí-SC
A6: Referência | B6: 7899516388428
A7: URL | B7: lunfemalhas.com.br/camiseta-custo-inteligente-atacado-malha-pa-lunfe
A8: Categoria no site | B8: Camisetas › Masculino › Regular Fit
A9: Linha HMZT recomendada | B9: Uniformes & Eventos (B2B) — fora da vitrine
A10: Estoque | B10: 6 cores em estoque; despacho em 24h úteis
A11: Descritor canônico (IA) | B11: Camiseta masculina regular fit, manga curta reta até o meio do bíceps, gola careca em ribana fina 1×1 de 2 cm sem pesponto aparente, meia malha leve de algodão com poliéster (160 g/m²), superfície lisa e fosca, cinza claro com aspecto mesclado, caimento leve que acompanha o corpo, barra dupla reta no quadril. Peça lisa, sem logos. Fundo cinza claro de estúdio.
A13: 2. Especificação técnica
A14: Item | B14: Valor | C14: Fonte
A15: Composição | B15: Meia malha algodão + poliéster — % não informado
A16: Gramatura | B16: 160 g/m²
A17: Modelagem | B17: Regular fit
A18: Gola | B18: Ribana 1×1, 2 cm, desagulhada (sem pesponto externo)
A19: Acabamentos | B19: Fita de cadarço ombro a ombro, ponto cadeia, barra dupla
A20: Tratamentos | B20: Pré-encolhimento mecânico, fixação de cor
A21: Tamanhos | B21: P, M, G, GG, EG
A22: Sigla 'PA' | B22: No mercado PA = poliamida; aqui usada para poliéster/algodão
A23: Secagem | B23: 'Seca 2–3× mais rápido que 100% algodão'
A24: Percepção | B24: '90% da percepção por 50% do custo'
A25: Produção | B25: Fabricação própria — Itajaí, SC
A27: 3. Tabela de medidas (cm)
A28: Tamanho | B28: Comprimento | C28: Largura | D28: Ombros | E28: Mangas
A29: P | B29: 70 | C29: 52 | D29: 44 | E29: 16
A30: M | B30: 72 | C30: 54 | D30: 46 | E30: 18
A31: G | B31: 74 | C31: 56 | D31: 48 | E31: 20
A32: GG | B32: 76 | C32: 58 | D32: 50 | E32: 22
A33: EG | B33: 78 | C33: 60 | D33: 52 | E33: 24
A34: Molde regular único Lunfe, em cm, ± 2 cm. Modelo 1,84 m / 84 kg veste M.
A35: Modelo das fotos: 1,84 m · 84 kg · veste M
A37: 4. Cores disponíveis
A38: Cor | B38: Código HMZT | C38: Ref. fornecedor | D38: Observação
A39: Preto | B39: PRT | C39: CIN-PRT
A40: Branco | B40: BCO | C40: CIN-BRA
A41: Marinho | B41: MAR | C41: CIN-MRN | D41: ⚠️ foto mostra azul royal
A42: Cinza Claro | B42: CZC | C42: CIN-CZC | D42: Mescla clara
A43: Bege | B43: BGE | C43: CIN-BGE
A44: Azul Bebê | B44: AZB | C44: CIN-AZB | D44: Sem foto
...

Sheet P12
A1: P12 — Camiseta Malhão Compact Algodão BCI 280g
A3: 1. Identificação
A4: Código HMZT | B4: HMZT-P12-REG-BCI280
A5: Fornecedor | B5: Lunfe Malhas — fabricação própria, Itajaí-SC
A6: Referência | B6: 7908365100783
A7: URL | B7: lunfemalhas.com.br/camiseta-malhao-compact-atacado-algodao-bci-lunfe
A8: Categoria no site | B8: Camisetas › Masculino › Regular Fit
A9: Linha HMZT recomendada | B9: Heavy — regular 100% algodão
A10: Estoque | B10: Disponibilidade imediata; 8 cores; despacho em 24h úteis
A11: Descritor canônico (IA) | B11: Camiseta masculina regular fit heavyweight, manga curta reta até o meio do bíceps com barra dupla, gola careca de ribana 2/1 firme e rente, malha 100% algodão de 280 g/m² densa e fosca com trama compacta levemente granulada, caimento estruturado que se sustenta sem colar, barra reta no quadril. Peça lisa, sem logos. Fundo cinza claro de estúdio.
A13: 2. Especificação técnica
A14: Item | B14: Valor | C14: Fonte
A15: Composição | B15: 100% algodão BCI
A16: Fio | B16: 26/1 penteado 'compact' (texto chama de 'fio fino' — é mais grosso que 30/1)
A17: Gramatura | B17: 280 g/m²
A18: Modelagem | B18: Regular fit unissex (tabela masculina)
A19: Gola | B19: Ribana 2/1
A20: Costuras | B20: Reforçadas, ponto conjugado
A21: Tratamentos | B21: Pré-encolhida
A22: BCI | B22: Declarado; sem comprovante; BCI não garante rastreabilidade física
A23: OEKO-TEX | B23: Declarado; sem nº de certificado
A24: Sustentável | B24: 'Premium sustentável', 'consciência ambiental'
A25: Produção | B25: Fabricação própria — Itajaí, SC
A27: 3. Tabela de medidas (cm)
A28: Tamanho | B28: Comprimento | C28: Largura | D28: Ombros | E28: Mangas
A29: P | B29: 70 | C29: 52 | D29: 44 | E29: 16
A30: M | B30: 72 | C30: 54 | D30: 46 | E30: 18
A31: G | B31: 74 | C31: 56 | D31: 48 | E31: 20
A32: GG | B32: 76 | C32: 58 | D32: 50 | E32: 22
A33: EG | B33: 78 | C33: 60 | D33: 52 | E33: 24
A34: Molde regular único Lunfe, em cm, variação 1–2 cm. Modelo 1,84 m / 84 kg veste M. ⚠️ Vendido como unissex com a tabela masculina — pedir grade feminina/PP.
A35: Modelo das fotos: 1,84 m · 84 kg · veste M
A37: 4. Cores disponíveis
A38: Cor | B38: Código HMZT | C38: Ref. fornecedor | D38: Observação
A39: Grafite | B39: GRF | C39: — | D39: Seletor 'Grafitte'; cinza escuro arroxeado nas fotos
A40: Off White | B40: OFF | C40: —
A41: Terracota | B41: TER | C41: — | D41: Sem foto
A42: Marrom | B42: MRR | C42: — | D42: Sem foto
A43: Caramelo | B43: CAR | C43: —
A44: Bege | B44: BGE | C44: — | D44: Sem foto
...

Sheet P13
A1: P13 — Camiseta Estonada Regular 175g (Outras Cores)
A3: 1. Identificação
A4: Código HMZT | B4: HMZT-P13-REG-EST175
A5: Fornecedor | B5: Lunfe Malhas — fabricação própria, Itajaí-SC
A6: Referência | B6: 7897564701282
A7: URL | B7: lunfemalhas.com.br/camiseta-estonada-atacado-algodao-penteado-lunfe-oc
A8: Categoria no site | B8: Camisetas › Masculino › Regular Fit
A9: Linha HMZT recomendada | B9: Lavada/Vintage (nova) — base regular
A10: Estoque | B10: Disponibilidade imediata na página (6 cores no seletor); widget de relacionados mostra "Esse acabou" — widget não confiável
A11: Descritor canônico (IA) | B11: Camiseta masculina regular fit, manga curta, algodão penteado 175 g estonado (stone wash): cor lavada irregular em nuvens, mais clara nas costuras, na borda da gola canelada 2/1, nas barras e nos ombros; superfície fosca e macia. Barra reta no quadril. Peça lisa, sem logos. Fundo cinza claro de estúdio.
A13: 2. Especificação técnica
A14: Item | B14: Valor | C14: Fonte
A15: Composição | B15: 100% algodão penteado
A16: Fio | B16: 30/1 penteado
A17: Gramatura | B17: 175 g/m² (texto) × 180 GSM (banner da galeria)
A18: Modelagem | B18: Regular (tabela padrão Lunfe)
A19: Acabamento | B19: Stone wash (lavagem com pedras-pomes) após a confecção + fixação pós-estonagem
A20: Gola | B20: Canelada 2/1, fecho em anel, reforço ombro a ombro
A21: Costuras | B21: Ponto cadeia; barra dupla em mangas e barra
A22: Tratamentos | B22: Pré-encolhimento, anti-torção, amaciamento
A23: Tamanhos | B23: P ao EG (5)
A24: Produção | B24: Fabricação própria Lunfe — Itajaí-SC
A25: Toque | B25: "Ultra macio, como camiseta lavada 50 vezes"
A26: Cor | B26: "Não progride nas lavagens domésticas"
A27: Modelo das fotos | B27: 1,79 m / 82 kg (texto) × 1,84 m / 84 kg (P14, mesmo modelo)
A29: 3. Tabela de medidas (cm)
A30: Tamanho | B30: Comprimento | C30: Largura | D30: Ombros | E30: Mangas
A31: P | B31: 70 | C31: 52 | D31: 44 | E31: 16
A32: M | B32: 72 | C32: 54 | D32: 46 | E32: 18
A33: G | B33: 74 | C33: 56 | D33: 48 | E33: 20
A34: GG | B34: 76 | C34: 58 | D34: 50 | E34: 22
A35: EG | B35: 78 | C35: 60 | D35: 52 | E35: 24
A36: Mesma tabela regular do P14 (± 1–2 cm). ⚠️ Esta página diz que o modelo tem 1,79 m / 82 kg; o P14 diz 1,84 m / 84 kg — é a mesma pessoa, na mesma sessão de fotos.
A37: Modelo das fotos: 1,84 m · 84 kg · veste M
A39: 4. Cores disponíveis
A40: Cor | B40: Código HMZT | C40: Ref. fornecedor | D40: Observação
A41: Verde Floresta | B41: VFL | C41: n/i | D41: Verde garrafa lavado (fotos #1–4)
A42: Índigo | B42: IND | C42: n/i | D42: Sem foto clara — talvez o tom ameixa das fotos #11–13 ⚠️
A43: Cinza | B43: CIN | C43: n/i | D43: Cinza médio lavado (fotos #5–7)
A44: Laranja Claro | B44: LRC | C44: n/i | D44: Pêssego (fotos #8–10) — parece o "Damasco" do P14
...

Sheet P14
A1: P14 — Camiseta Estonada Regular 175g
A3: 1. Identificação
A4: Código HMZT | B4: HMZT-P14-REG-EST175
A5: Fornecedor | B5: Lunfe Malhas — fabricação própria, Itajaí-SC
A6: Referência | B6: 7892948548590
A7: URL | B7: lunfemalhas.com.br/camiseta-estonada-atacado-algodao-penteado-30-1-lunfe
A8: Categoria no site | B8: Camisetas › Masculino › Regular Fit
A9: Linha HMZT recomendada | B9: Lavada/Vintage (nova) — base regular
A10: Estoque | B10: Disponibilidade imediata na página (6 cores); o widget de relacionados das outras páginas mostra "Esse acabou" — widget não confiável
A11: Descritor canônico (IA) | B11: Camiseta masculina regular fit, manga curta, algodão penteado 175 g estonado (stone wash): cor lavada irregular em nuvens, mais clara nas costuras, na borda da gola canelada 2/1, nas barras e nos ombros; superfície fosca e macia. Barra reta no quadril. Peça lisa, sem logos. Fundo cinza claro de estúdio.
A13: 2. Especificação técnica
A14: Item | B14: Valor | C14: Fonte
A15: Composição | B15: 100% algodão penteado
A16: Fio | B16: 30/1 penteado
A17: Gramatura | B17: 175 g/m² (texto) × 180 GSM (banner da galeria)
A18: Modelagem | B18: Regular (tabela padrão Lunfe)
A19: Acabamento | B19: Stone wash (lavagem com pedras-pomes) após a confecção + fixação pós-estonagem
A20: Gola | B20: Canelada 2/1, fecho em anel, reforço ombro a ombro
A21: Costuras | B21: Ponto cadeia; barra dupla em mangas e barra
A22: Tratamentos | B22: Pré-encolhimento, anti-torção, amaciamento
A23: Tamanhos | B23: P ao EG (5)
A24: Produção | B24: Fabricação própria Lunfe — Itajaí-SC
A25: Toque | B25: "Ultra macio, como camiseta lavada 50 vezes"
A26: Cor | B26: "Não progride nas lavagens domésticas"
A28: 3. Tabela de medidas (cm)
A29: Tamanho | B29: Comprimento | C29: Largura | D29: Ombros | E29: Mangas
A30: P | B30: 70 | C30: 52 | D30: 44 | E30: 16
A31: M | B31: 72 | C31: 54 | D31: 46 | E31: 18
A32: G | B32: 74 | C32: 56 | D32: 48 | E32: 20
A33: GG | B33: 76 | C33: 58 | D33: 50 | E33: 22
A34: EG | B34: 78 | C34: 60 | D34: 52 | E34: 24
A35: Tabela regular padrão Lunfe (± 2 cm, + até 1 cm pela estonagem). Modelo 1,84 m / 84 kg veste M.
A36: Modelo das fotos: 1,84 m · 84 kg · veste M
A38: 4. Cores disponíveis
A39: Cor | B39: Código HMZT | C39: Ref. fornecedor | D39: Observação
A40: Preto estonado | B40: PRT | C40: EST-PRT | D40: Desgaste sutil — vira grafite lavado (foto #1)
A41: Marinho estonado | B41: MAR | C41: EST-MRN | D41: Desgaste médio (fotos #11–14)
A42: Damasco estonado | B42: DMS | C42: EST-DMS | D42: Pêssego claro (foto #15) — parece igual ao "Laranja Claro" do P13
A43: Laranja estonado | B43: LRJ | C43: EST-LRJ | D43: Coral forte nas fotos #4–7
A44: Bege estonado | B44: BGE | C44: EST-BGE | D44: Areia clara (fotos #8–10)
...

Sheet P15
A1: P15 — Camiseta Estonada Neon Regular 175g
A3: 1. Identificação
A4: Código HMZT | B4: HMZT-P15-REG-ESN175
A5: Fornecedor | B5: Lunfe Malhas — fabricação própria, Itajaí-SC
A6: Referência | B6: código interno ESTON#NEON/24
A7: URL | B7: lunfemalhas.com.br/camiseta-estonada-neon-atacado-algodao-penteado-lunfe
A8: Categoria no site | B8: Camisetas › Masculino › Regular Fit
A9: Linha HMZT recomendada | B9: Lavada/Vintage — cápsula de verão (drop)
A10: Estoque | B10: Disponibilidade imediata (6 cores neon)
A11: Descritor canônico (IA) | B11: Camiseta masculina regular fit, manga curta, algodão penteado 175 g em cor neon fluorescente, fosca, com lavagem leve e irregular (levemente mesclada, mais clara nas costuras e na borda da gola canelada 2/1). Barra reta no quadril. Peça lisa, sem logos. Fundo cinza claro de estúdio.
A13: 2. Especificação técnica
A14: Item | B14: Valor | C14: Fonte
A15: Composição | B15: 100% algodão penteado
A16: Fio | B16: 30/1 penteado
A17: Gramatura | B17: 175 g/m² (texto) × 180 GSM (banner da galeria)
A18: Modelagem | B18: Regular (tabela padrão Lunfe)
A19: Cores | B19: 6 neon — solidez à luz não informada
A20: Acabamento | B20: Stone wash (lavagem com pedras-pomes) após a confecção + fixação pós-estonagem
A21: Gola | B21: Canelada 2/1, fecho em anel, reforço ombro a ombro
A22: Costuras | B22: Ponto cadeia; barra dupla em mangas e barra
A23: Tratamentos | B23: Pré-encolhimento, anti-torção, amaciamento
A24: Tamanhos | B24: P ao EG (5)
A25: Produção | B25: Fabricação própria Lunfe — Itajaí-SC
A26: Toque | B26: "Ultra macio, como camiseta lavada 50 vezes"
A27: Cor | B27: "Não progride nas lavagens domésticas"
A29: 3. Tabela de medidas (cm)
A30: Tamanho | B30: Comprimento | C30: Largura | D30: Ombros | E30: Mangas
A31: P | B31: 70 | C31: 52 | D31: 44 | E31: 16
A32: M | B32: 72 | C32: 54 | D32: 46 | E32: 18
A33: G | B33: 74 | C33: 56 | D33: 48 | E33: 20
A34: GG | B34: 76 | C34: 58 | D34: 50 | E34: 22
A35: EG | B35: 78 | C35: 60 | D35: 52 | E35: 24
A36: Mesma tabela regular do P14 (± 1–2 cm). ⚠️ Texto diz modelo 1,79 m / 82 kg — é o mesmo modelo das fotos do P13/P14 (que o P14 diz ter 1,84 m / 84 kg).
A37: Modelo das fotos: 1,84 m · 84 kg · veste M
A39: 4. Cores disponíveis
A40: Cor | B40: Código HMZT | C40: Ref. fornecedor | D40: Observação
A41: Verde Neon | B41: VNN | C41: n/i | D41: Fotos #6–8
A42: Laranja Neon | B42: LRN | C42: n/i | D42: Fotos #1, #2, #5
A43: Amarelo Neon | B43: AMN | C43: n/i | D43: Amarelo-limão (fotos #14–16)
A44: Azul Neon | B44: AZN | C44: n/i | D44: Azul-turquesa (fotos #18–21)
...

Sheet P16
A1: P16 — Camiseta Estonada Oversized 175g
A3: 1. Identificação
A4: Código HMZT | B4: HMZT-P16-OVS-EST175
A5: Fornecedor | B5: Lunfe Malhas — fabricação própria, Itajaí-SC
A6: Referência | B6: código interno 30/1OVR/LF
A7: URL | B7: lunfemalhas.com.br/camiseta-estonada-oversized-atacado-algodao-penteado-lunfe
A8: Categoria no site | B8: Camisetas › Masculino › Oversized
A9: Linha HMZT recomendada | B9: Lavada/Vintage (nova) — base oversized
A10: Estoque | B10: Disponibilidade imediata (15 cores); widget de relacionados mostra "Esse acabou" — não confiável
A11: Descritor canônico (IA) | B11: Camiseta masculina oversized, ombro caído, corpo amplo e alongado abaixo do quadril, mangas largas até acima do cotovelo, algodão penteado 175 g estonado: cor lavada irregular, mais clara nas costuras, gola canelada e barras; caimento mole com dobras verticais. Peça lisa, sem logos. Fundo cinza claro de estúdio.
A13: 2. Especificação técnica
A14: Item | B14: Valor | C14: Fonte
A15: Composição | B15: 100% algodão penteado
A16: Fio | B16: 30/1 penteado
A17: Gramatura | B17: 175 g/m² (texto) × 180 GSM (banner da galeria)
A18: Modelagem | B18: Oversized (ombro caído, corpo amplo e alongado)
A19: Acabamento | B19: Stone wash (lavagem com pedras-pomes) após a confecção + fixação pós-estonagem
A20: Gola | B20: Canelada 2/1, fecho em anel, reforço ombro a ombro
A21: Costuras | B21: Ponto cadeia; barra dupla em mangas e barra
A22: Tratamentos | B22: Pré-encolhimento, anti-torção, amaciamento
A23: Tamanhos | B23: P ao EG (5)
A24: Produção | B24: Fabricação própria Lunfe — Itajaí-SC
A25: Toque | B25: "Ultra macio, como camiseta lavada 50 vezes"
A26: Cor | B26: "Não progride nas lavagens domésticas"
A28: 3. Tabela de medidas (cm)
A29: Tamanho | B29: Comprimento | C29: Largura | D29: Ombros | E29: Mangas
A30: P | B30: 73 | C30: 57 | D30: 52 | E30: 24
A31: M | B31: 75 | C31: 59 | D31: 54 | E31: 25
A32: G | B32: 77 | C32: 61 | D32: 56 | E32: 26
A33: GG | B33: 79 | C33: 63 | D33: 58 | E33: 27
A34: EG | B34: 81 | C34: 65 | D34: 60 | E34: 28
A35: Tabela oversized própria (± 1–2 cm). Modelo 1,84 m / 84 kg veste M. ⚠️ Mangas crescem 1 cm por tamanho aqui e 2 cm no P17, embora o texto diga que a modelagem é a mesma.
A36: Modelo das fotos: 1,84 m · 84 kg · veste M
A38: 4. Cores disponíveis
A39: Cor | B39: Código HMZT | C39: Ref. fornecedor | D39: Observação
A40: Verde Musgo | B40: VMG | C40: n/i | D40: Foto #13
A41: Chumbo | B41: CHU | C41: n/i | D41: Marrom-grafite (foto #14)
A42: Azul Jeans | B42: AJN | C42: n/i | D42: Azul acinzentado (foto #17)
A43: Cereja | B43: CRJ | C43: n/i | D43: Vermelho-framboesa (foto #16)
A44: Castanho | B44: CST | C44: n/i | D44: Caramelo (foto #6)
...

Sheet P17
A1: P17 — Camiseta Estonada Oversized com Bolso 175g
A3: 1. Identificação
A4: Código HMZT | B4: HMZT-P17-OVS-ESB175
A5: Fornecedor | B5: Lunfe Malhas — fabricação própria, Itajaí-SC
A6: Referência | B6: 7896976920472
A7: URL | B7: lunfemalhas.com.br/camiseta-estonada-oversized-bolso-atacado-algodao-penteado-lunfe
A8: Categoria no site | B8: Camisetas › Masculino › Oversized
A9: Linha HMZT recomendada | B9: Lavada/Vintage — destaque oversized com bolso (após reposição)
A10: Estoque | B10: 🔴 "Esse acabou" na própria página (sem seletor, sem preço no topo, sem "Disponibilidade")
A11: Descritor canônico (IA) | B11: Camiseta masculina oversized com bolso quadrado no peito esquerdo, ombro caído, corpo amplo abaixo do quadril, algodão penteado 175 g estonado: cor lavada irregular, mais clara nas costuras, na borda do bolso, na gola canelada e nas barras. Peça lisa, sem logos. Fundo cinza claro de estúdio.
A13: 2. Especificação técnica
A14: Item | B14: Valor | C14: Fonte
A15: Composição | B15: 100% algodão penteado
A16: Fio | B16: 30/1 penteado
A17: Gramatura | B17: 175 g/m² (texto) × 180 GSM (banner da galeria)
A18: Modelagem | B18: Oversized com bolso no peito
A19: Detalhe | B19: Bolso frontal no peito, aplicado antes da lavagem
A20: Acabamento | B20: Stone wash (lavagem com pedras-pomes) após a confecção + fixação pós-estonagem
A21: Gola | B21: Canelada 2/1, fecho em anel, reforço ombro a ombro
A22: Costuras | B22: Ponto cadeia; barra dupla em mangas e barra
A23: Tratamentos | B23: Pré-encolhimento, anti-torção, amaciamento
A24: Tamanhos | B24: P ao EG (5)
A25: Produção | B25: Fabricação própria Lunfe — Itajaí-SC
A26: Toque | B26: "Ultra macio, como camiseta lavada 50 vezes"
A27: Cor | B27: "Não progride nas lavagens domésticas"
A29: 3. Tabela de medidas (cm)
A30: Tamanho | B30: Comprimento | C30: Largura | D30: Ombros | E30: Mangas
A31: P | B31: 73 | C31: 57 | D31: 52 | E31: 22
A32: M | B32: 75 | C32: 59 | D32: 54 | E32: 24
A33: G | B33: 77 | C33: 61 | D33: 56 | E33: 26
A34: GG | B34: 79 | C34: 63 | D34: 58 | E34: 28
A35: EG | B35: 81 | C35: 65 | D35: 60 | E35: 30
A36: Tabela própria (± 1–2 cm), pré-encolhida. Modelo 1,84 m / 84 kg veste M. ⚠️ Mangas diferem do P16 (M 24 × 25; EG 30 × 28), embora o texto diga "mesma modelagem".
A37: Modelo das fotos: 1,84 m · 84 kg · veste M
